Setting SECRET_KEY in ini file
[prerun] CKAN_SQLALCHEMY_URL not defined, skipping DB URL update
[prerun] Updating ckan.site_url in /srv/app/ckan.ini to http://localhost:5000
[prerun] ckan.site_url updated successfully.
[prerun] CKAN_SQLALCHEMY_URL not defined, not checking db
[prerun] Initializing or upgrading db - start
[prerun] Database not ready, waiting a bit before exit...
/srv/app/start_ckan.sh: Running init file /docker-entrypoint.d/02_setup_xloader.sh
************************SETUP XLOADER FILE************************
CKAN_INI = /srv/app/ckan.ini
CKAN__PLUGINS = image_view text_view datatables_view datastore envvars
CKAN__XLOADER__API_TOKEN = <not set>
---------------------------------------------------------------
Not configuring xloader
/srv/app/start_ckan.sh: Running init file /docker-entrypoint.d/03_allow_create_user.sh
Updated CKAN user creation settings in /srv/app/ckan.ini
/srv/app/start_ckan.sh: Ignoring /docker-entrypoint.d/README.md (not an sh or py file)
2025-10-28 20:05:55,376 INFO [ckan.cli] Using configuration file /srv/app/ckan.ini
2025-10-28 20:05:55,376 INFO [ckan.config.environment] Loading static files from public
2025-10-28 20:05:55,945 WARNI [ckan.common] Option lang is not declared
2025-10-28 20:05:56,049 ERROR [ckan.lib.search.common] Failed to connect to server at http://127.0.0.1:8983/solr/ckan/select/?q=%2A%3A%2A&rows=1&wt=json: HTTPConnectionPool(host='127.0.0.1', port=8983): Max retries exceeded with url: /solr/ckan/select/?q=%2A%3A%2A&rows=1&wt=json (Caused by NewConnectionError('<urllib3.connection.HTTPConnection object at 0x7f678e893ee0>: Failed to establish a new connection: [Errno 111] Connection refused'))
Traceback (most recent call last):
File "/usr/local/lib/python3.10/site-packages/urllib3/connection.py", line 196, in _new_conn
sock = connection.create_connection(
File "/usr/local/lib/python3.10/site-packages/urllib3/util/connection.py", line 85, in create_connection
raise err
File "/usr/local/lib/python3.10/site-packages/urllib3/util/connection.py", line 73, in create_connection
sock.connect(sa)
ConnectionRefusedError: [Errno 111] Connection refused
The above exception was the direct cause of the following exception:
Traceback (most recent call last):
File "/usr/local/lib/python3.10/site-packages/urllib3/connectionpool.py", line 789, in urlopen
response = self._make_request(
File "/usr/local/lib/python3.10/site-packages/urllib3/connectionpool.py", line 495, in _make_request
conn.request(
File "/usr/local/lib/python3.10/site-packages/urllib3/connection.py", line 398, in request
self.endheaders()
File "/usr/local/lib/python3.10/http/client.py", line 1278, in endheaders
self._send_output(message_body, encode_chunked=encode_chunked)
File "/usr/local/lib/python3.10/http/client.py", line 1038, in _send_output
self.send(msg)





File "/usr/local/lib/python3.10/site-packages/sqlalchemy/engine/reflection.py", line 128, in _init_engine
engine.connect().close()
File "/usr/local/lib/python3.10/site-packages/sqlalchemy/engine/base.py", line 3325, in connect
return self._connection_cls(self, close_with_result=close_with_result)
File "/usr/local/lib/python3.10/site-packages/sqlalchemy/engine/base.py", line 96, in __init__
else engine.raw_connection()
File "/usr/local/lib/python3.10/site-packages/sqlalchemy/engine/base.py", line 3404, in raw_connection
return self._wrap_pool_connect(self.pool.connect, _connection)
File "/usr/local/lib/python3.10/site-packages/sqlalchemy/engine/base.py", line 3374, in _wrap_pool_connect
Connection._handle_dbapi_exception_noconnection(
File "/usr/local/lib/python3.10/site-packages/sqlalchemy/engine/base.py", line 2208, in _handle_dbapi_exception_noconnection
util.raise_(
File "/usr/local/lib/python3.10/site-packages/sqlalchemy/util/compat.py", line 211, in raise_
raise exception
File "/usr/local/lib/python3.10/site-packages/sqlalchemy/engine/base.py", line 3371, in _wrap_pool_connect
return fn()
File "/usr/local/lib/python3.10/site-packages/sqlalchemy/pool/base.py", line 327, in connect
return _ConnectionFairy._checkout(self)
File "/usr/local/lib/python3.10/site-packages/sqlalchemy/pool/base.py", line 894, in _checkout
fairy = _ConnectionRecord.checkout(pool)
File "/usr/local/lib/python3.10/site-packages/sqlalchemy/pool/base.py", line 493, in checkout
rec = pool._do_get()
File "/usr/local/lib/python3.10/site-packages/sqlalchemy/pool/impl.py", line 145, in _do_get
with util.safe_reraise():
File "/usr/local/lib/python3.10/site-packages/sqlalchemy/util/langhelpers.py", line 70, in __exit__
compat.raise_(
File "/usr/local/lib/python3.10/site-packages/sqlalchemy/util/compat.py", line 211, in raise_
raise exception
File "/usr/local/lib/python3.10/site-packages/sqlalchemy/pool/impl.py", line 143, in _do_get
return self._create_connection()
File "/usr/local/lib/python3.10/site-packages/sqlalchemy/pool/base.py", line 273, in _create_connection
return _ConnectionRecord(self)
File "/usr/local/lib/python3.10/site-packages/sqlalchemy/pool/base.py", line 388, in __init__
self.__connect()
File "/usr/local/lib/python3.10/site-packages/sqlalchemy/pool/base.py", line 690, in __connect
with util.safe_reraise():
File "/usr/local/lib/python3.10/site-packages/sqlalchemy/util/langhelpers.py", line 70, in __exit__
compat.raise_(
File "/usr/local/lib/python3.10/site-packages/sqlalchemy/util/compat.py", line 211, in raise_
raise exception
File "/usr/local/lib/python3.10/site-packages/sqlalchemy/pool/base.py", line 686, in __connect
self.dbapi_connection = connection = pool._invoke_creator(self)
File "/usr/local/lib/python3.10/site-packages/sqlalchemy/engine/create.py", line 574, in connect
return dialect.connect(*cargs, **cparams)
File "/usr/local/lib/python3.10/site-packages/sqlalchemy/engine/default.py", line 598, in connect
return self.dbapi.connect(*cargs, **cparams)
File "/usr/local/lib/python3.10/site-packages/psycopg2/__init__.py", line 122, in connect
conn = _connect(dsn, connection_factory=connection_factory, **kwasync)
sqlalchemy.exc.OperationalError: (psycopg2.OperationalError) connection to server at "localhost" (::1), port 5432 failed: Connection refused
Is the server running on that host and accepting TCP/IP connections?
connection to server at "localhost" (127.0.0.1), port 5432 failed: Connection refused
Is the server running on that host and accepting TCP/IP connections?
(Background on this error at: https://sqlalche.me/e/14/e3q8)